2025-04-23 23:06:28,346:WARNING:discord.client: PyNaCl is not installed, voice will NOT be supported
2025-04-23 23:06:28,348:INFO:discord.client: logging in using static token
2025-04-23 23:06:29,523:INFO:discord.gateway: Shard ID None has connected to Gateway (Session ID: 1b08198be2cb3225db8dec2e93b9b351).
2025-04-23 23:06:31,537:INFO:discord: Logged in as Github Logger (ID: 1178558163486777344)
2025-04-23 23:06:31,537:INFO:discord: Monitoring GitHub Repo: Moharoon777/Final_Year
2025-04-23 23:06:31,537:INFO:discord: Notifications will be sent to Channel ID: 1023368825162444841
2025-04-23 23:06:31,538:INFO:discord: Check interval: 300 seconds
2025-04-23 23:06:31,538:INFO:discord: ------
2025-04-23 23:06:31,538:INFO:discord: Bot is ready, starting GitHub commit check loop...
2025-04-23 23:06:31,538:INFO:discord: Performing initial commit check to set baseline...
2025-04-23 23:06:31,875:INFO:discord: Baseline commit SHA set to: c4d1fa2
2025-04-23 23:06:31,876:INFO:discord: Checking for new commits...
2025-04-23 23:06:32,164:INFO:discord: No new commits found.
2025-04-23 23:11:31,879:INFO:discord: Checking for new commits...
2025-04-23 23:11:33,231:INFO:discord: No new commits found.
2025-04-23 23:16:31,877:INFO:discord: Checking for new commits...
2025-04-23 23:16:32,217:INFO:discord: New commit detected! SHA: 0ee5bca
2025-04-23 23:16:32,217:ERROR:discord: Could not find channel with ID: 1023368825162444841. Make sure the ID is correct and the bot is in the server.
2025-04-23 23:21:31,888:INFO:discord: Checking for new commits...
2025-04-23 23:21:32,247:INFO:discord: New commit detected! SHA: 0ee5bca
2025-04-23 23:21:32,248:ERROR:discord: Could not find channel with ID: 1023368825162444841. Make sure the ID is correct and the bot is in the server.
2025-04-23 23:26:31,885:INFO:discord: Checking for new commits...
2025-04-23 23:26:32,280:INFO:discord: New commit detected! SHA: 0ee5bca
2025-04-23 23:26:32,656:INFO:discord: Notification sent to channel 1023368825162444841 for commit 0ee5bca
2025-04-23 23:27:48,622:INFO:discord.gateway: Shard ID None has successfully RESUMED session 1b08198be2cb3225db8dec2e93b9b351.
2025-04-23 23:31:31,884:INFO:discord: Checking for new commits...
2025-04-23 23:31:33,478:INFO:discord: No new commits found.
2025-04-23 23:36:31,878:INFO:discord: Checking for new commits...
2025-04-23 23:36:32,697:INFO:discord: No new commits found.
2025-04-23 23:41:31,885:INFO:discord: Checking for new commits...
2025-04-23 23:41:32,732:INFO:discord: No new commits found.
2025-04-23 23:46:31,885:INFO:discord: Checking for new commits...
2025-04-23 23:46:32,560:INFO:discord: No new commits found.
2025-04-23 23:48:04,173:ERROR:discord.client: Attempting a reconnect in 0.75s
Traceback (most recent call last):
  File "C:\Users\colij\Documents\Repo_Tracker_Bot\env\Lib\site-packages\aiohttp\connector.py", line 1351, in _create_direct_connection
    hosts = await self._resolve_host(host, port, traces=traces)
            ^^^^^^^^^^^^^^^^^^^^^^^^^^^^^^^^^^^^^^^^^^^^^^^^^^^
  File "C:\Users\colij\Documents\Repo_Tracker_Bot\env\Lib\site-packages\aiohttp\connector.py", line 995, in _resolve_host
    return await asyncio.shield(resolved_host_task)
           ^^^^^^^^^^^^^^^^^^^^^^^^^^^^^^^^^^^^^^^^
  File "C:\Users\colij\Documents\Repo_Tracker_Bot\env\Lib\site-packages\aiohttp\connector.py", line 1026, in _resolve_host_with_throttle
    addrs = await self._resolver.resolve(host, port, family=self._family)
            ^^^^^^^^^^^^^^^^^^^^^^^^^^^^^^^^^^^^^^^^^^^^^^^^^^^^^^^^^^^^^
  File "C:\Users\colij\Documents\Repo_Tracker_Bot\env\Lib\site-packages\aiohttp\resolver.py", line 39, in resolve
    infos = await self._loop.getaddrinfo(
            ^^^^^^^^^^^^^^^^^^^^^^^^^^^^^
    ...<5 lines>...
    )
    ^
  File "C:\Program Files\Python313\Lib\asyncio\base_events.py", line 935, in getaddrinfo
    return await self.run_in_executor(
           ^^^^^^^^^^^^^^^^^^^^^^^^^^^
        None, getaddr_func, host, port, family, type, proto, flags)
        ^^^^^^^^^^^^^^^^^^^^^^^^^^^^^^^^^^^^^^^^^^^^^^^^^^^^^^^^^^^
  File "C:\Program Files\Python313\Lib\concurrent\futures\thread.py", line 58, in run
    result = self.fn(*self.args, **self.kwargs)
  File "C:\Program Files\Python313\Lib\socket.py", line 975, in getaddrinfo
    for res in _socket.getaddrinfo(host, port, family, type, proto, flags):
               ~~~~~~~~~~~~~~~~~~~^^^^^^^^^^^^^^^^^^^^^^^^^^^^^^^^^^^^^^^^
socket.gaierror: [Errno 11001] getaddrinfo failed

The above exception was the direct cause of the following exception:

Traceback (most recent call last):
  File "C:\Users\colij\Documents\Repo_Tracker_Bot\env\Lib\site-packages\discord\client.py", line 701, in connect
    self.ws = await asyncio.wait_for(coro, timeout=60.0)
              ^^^^^^^^^^^^^^^^^^^^^^^^^^^^^^^^^^^^^^^^^^
  File "C:\Program Files\Python313\Lib\asyncio\tasks.py", line 507, in wait_for
    return await fut
           ^^^^^^^^^
  File "C:\Users\colij\Documents\Repo_Tracker_Bot\env\Lib\site-packages\discord\gateway.py", line 375, in from_client
    socket = await client.http.ws_connect(str(url))
             ^^^^^^^^^^^^^^^^^^^^^^^^^^^^^^^^^^^^^^
  File "C:\Users\colij\Documents\Repo_Tracker_Bot\env\Lib\site-packages\discord\http.py", line 554, in ws_connect
    return await self.__session.ws_connect(url, **kwargs)
           ^^^^^^^^^^^^^^^^^^^^^^^^^^^^^^^^^^^^^^^^^^^^^^
  File "C:\Users\colij\Documents\Repo_Tracker_Bot\env\Lib\site-packages\aiohttp\client.py", line 1004, in _ws_connect
    resp = await self.request(
           ^^^^^^^^^^^^^^^^^^^
    ...<11 lines>...
    )
    ^
  File "C:\Users\colij\Documents\Repo_Tracker_Bot\env\Lib\site-packages\aiohttp\client.py", line 703, in _request
    conn = await self._connector.connect(
           ^^^^^^^^^^^^^^^^^^^^^^^^^^^^^^
        req, traces=traces, timeout=real_timeout
        ^^^^^^^^^^^^^^^^^^^^^^^^^^^^^^^^^^^^^^^^
    )
    ^
  File "C:\Users\colij\Documents\Repo_Tracker_Bot\env\Lib\site-packages\aiohttp\connector.py", line 548, in connect
    proto = await self._create_connection(req, traces, timeout)
            ^^^^^^^^^^^^^^^^^^^^^^^^^^^^^^^^^^^^^^^^^^^^^^^^^^^
  File "C:\Users\colij\Documents\Repo_Tracker_Bot\env\Lib\site-packages\aiohttp\connector.py", line 1056, in _create_connection
    _, proto = await self._create_direct_connection(req, traces, timeout)
               ^^^^^^^^^^^^^^^^^^^^^^^^^^^^^^^^^^^^^^^^^^^^^^^^^^^^^^^^^^
  File "C:\Users\colij\Documents\Repo_Tracker_Bot\env\Lib\site-packages\aiohttp\connector.py", line 1357, in _create_direct_connection
    raise ClientConnectorDNSError(req.connection_key, exc) from exc
aiohttp.client_exceptions.ClientConnectorDNSError: Cannot connect to host gateway-us-east1-c.discord.gg:443 ssl:default [getaddrinfo failed]
2025-04-23 23:48:05,835:ERROR:discord.client: Attempting a reconnect in 0.16s
Traceback (most recent call last):
  File "C:\Users\colij\Documents\Repo_Tracker_Bot\env\Lib\site-packages\aiohttp\connector.py", line 1351, in _create_direct_connection
    hosts = await self._resolve_host(host, port, traces=traces)
            ^^^^^^^^^^^^^^^^^^^^^^^^^^^^^^^^^^^^^^^^^^^^^^^^^^^
  File "C:\Users\colij\Documents\Repo_Tracker_Bot\env\Lib\site-packages\aiohttp\connector.py", line 995, in _resolve_host
    return await asyncio.shield(resolved_host_task)
           ^^^^^^^^^^^^^^^^^^^^^^^^^^^^^^^^^^^^^^^^
  File "C:\Users\colij\Documents\Repo_Tracker_Bot\env\Lib\site-packages\aiohttp\connector.py", line 1026, in _resolve_host_with_throttle
    addrs = await self._resolver.resolve(host, port, family=self._family)
            ^^^^^^^^^^^^^^^^^^^^^^^^^^^^^^^^^^^^^^^^^^^^^^^^^^^^^^^^^^^^^
  File "C:\Users\colij\Documents\Repo_Tracker_Bot\env\Lib\site-packages\aiohttp\resolver.py", line 39, in resolve
    infos = await self._loop.getaddrinfo(
            ^^^^^^^^^^^^^^^^^^^^^^^^^^^^^
    ...<5 lines>...
    )
    ^
  File "C:\Program Files\Python313\Lib\asyncio\base_events.py", line 935, in getaddrinfo
    return await self.run_in_executor(
           ^^^^^^^^^^^^^^^^^^^^^^^^^^^
        None, getaddr_func, host, port, family, type, proto, flags)
        ^^^^^^^^^^^^^^^^^^^^^^^^^^^^^^^^^^^^^^^^^^^^^^^^^^^^^^^^^^^
  File "C:\Program Files\Python313\Lib\concurrent\futures\thread.py", line 58, in run
    result = self.fn(*self.args, **self.kwargs)
  File "C:\Program Files\Python313\Lib\socket.py", line 975, in getaddrinfo
    for res in _socket.getaddrinfo(host, port, family, type, proto, flags):
               ~~~~~~~~~~~~~~~~~~~^^^^^^^^^^^^^^^^^^^^^^^^^^^^^^^^^^^^^^^^
socket.gaierror: [Errno 11001] getaddrinfo failed

The above exception was the direct cause of the following exception:

Traceback (most recent call last):
  File "C:\Users\colij\Documents\Repo_Tracker_Bot\env\Lib\site-packages\discord\client.py", line 701, in connect
    self.ws = await asyncio.wait_for(coro, timeout=60.0)
              ^^^^^^^^^^^^^^^^^^^^^^^^^^^^^^^^^^^^^^^^^^
  File "C:\Program Files\Python313\Lib\asyncio\tasks.py", line 507, in wait_for
    return await fut
           ^^^^^^^^^
  File "C:\Users\colij\Documents\Repo_Tracker_Bot\env\Lib\site-packages\discord\gateway.py", line 375, in from_client
    socket = await client.http.ws_connect(str(url))
             ^^^^^^^^^^^^^^^^^^^^^^^^^^^^^^^^^^^^^^
  File "C:\Users\colij\Documents\Repo_Tracker_Bot\env\Lib\site-packages\discord\http.py", line 554, in ws_connect
    return await self.__session.ws_connect(url, **kwargs)
           ^^^^^^^^^^^^^^^^^^^^^^^^^^^^^^^^^^^^^^^^^^^^^^
  File "C:\Users\colij\Documents\Repo_Tracker_Bot\env\Lib\site-packages\aiohttp\client.py", line 1004, in _ws_connect
    resp = await self.request(
           ^^^^^^^^^^^^^^^^^^^
    ...<11 lines>...
    )
    ^
  File "C:\Users\colij\Documents\Repo_Tracker_Bot\env\Lib\site-packages\aiohttp\client.py", line 703, in _request
    conn = await self._connector.connect(
           ^^^^^^^^^^^^^^^^^^^^^^^^^^^^^^
        req, traces=traces, timeout=real_timeout
        ^^^^^^^^^^^^^^^^^^^^^^^^^^^^^^^^^^^^^^^^
    )
    ^
  File "C:\Users\colij\Documents\Repo_Tracker_Bot\env\Lib\site-packages\aiohttp\connector.py", line 548, in connect
    proto = await self._create_connection(req, traces, timeout)
            ^^^^^^^^^^^^^^^^^^^^^^^^^^^^^^^^^^^^^^^^^^^^^^^^^^^
  File "C:\Users\colij\Documents\Repo_Tracker_Bot\env\Lib\site-packages\aiohttp\connector.py", line 1056, in _create_connection
    _, proto = await self._create_direct_connection(req, traces, timeout)
               ^^^^^^^^^^^^^^^^^^^^^^^^^^^^^^^^^^^^^^^^^^^^^^^^^^^^^^^^^^
  File "C:\Users\colij\Documents\Repo_Tracker_Bot\env\Lib\site-packages\aiohttp\connector.py", line 1357, in _create_direct_connection
    raise ClientConnectorDNSError(req.connection_key, exc) from exc
aiohttp.client_exceptions.ClientConnectorDNSError: Cannot connect to host gateway-us-east1-c.discord.gg:443 ssl:default [getaddrinfo failed]
2025-04-23 23:48:06,221:ERROR:discord.client: Attempting a reconnect in 3.40s
Traceback (most recent call last):
  File "C:\Users\colij\Documents\Repo_Tracker_Bot\env\Lib\site-packages\aiohttp\connector.py", line 1351, in _create_direct_connection
    hosts = await self._resolve_host(host, port, traces=traces)
            ^^^^^^^^^^^^^^^^^^^^^^^^^^^^^^^^^^^^^^^^^^^^^^^^^^^
  File "C:\Users\colij\Documents\Repo_Tracker_Bot\env\Lib\site-packages\aiohttp\connector.py", line 995, in _resolve_host
    return await asyncio.shield(resolved_host_task)
           ^^^^^^^^^^^^^^^^^^^^^^^^^^^^^^^^^^^^^^^^
  File "C:\Users\colij\Documents\Repo_Tracker_Bot\env\Lib\site-packages\aiohttp\connector.py", line 1026, in _resolve_host_with_throttle
    addrs = await self._resolver.resolve(host, port, family=self._family)
            ^^^^^^^^^^^^^^^^^^^^^^^^^^^^^^^^^^^^^^^^^^^^^^^^^^^^^^^^^^^^^
  File "C:\Users\colij\Documents\Repo_Tracker_Bot\env\Lib\site-packages\aiohttp\resolver.py", line 39, in resolve
    infos = await self._loop.getaddrinfo(
            ^^^^^^^^^^^^^^^^^^^^^^^^^^^^^
    ...<5 lines>...
    )
    ^
  File "C:\Program Files\Python313\Lib\asyncio\base_events.py", line 935, in getaddrinfo
    return await self.run_in_executor(
           ^^^^^^^^^^^^^^^^^^^^^^^^^^^
        None, getaddr_func, host, port, family, type, proto, flags)
        ^^^^^^^^^^^^^^^^^^^^^^^^^^^^^^^^^^^^^^^^^^^^^^^^^^^^^^^^^^^
  File "C:\Program Files\Python313\Lib\concurrent\futures\thread.py", line 58, in run
    result = self.fn(*self.args, **self.kwargs)
  File "C:\Program Files\Python313\Lib\socket.py", line 975, in getaddrinfo
    for res in _socket.getaddrinfo(host, port, family, type, proto, flags):
               ~~~~~~~~~~~~~~~~~~~^^^^^^^^^^^^^^^^^^^^^^^^^^^^^^^^^^^^^^^^
socket.gaierror: [Errno 11001] getaddrinfo failed

The above exception was the direct cause of the following exception:

Traceback (most recent call last):
  File "C:\Users\colij\Documents\Repo_Tracker_Bot\env\Lib\site-packages\discord\client.py", line 701, in connect
    self.ws = await asyncio.wait_for(coro, timeout=60.0)
              ^^^^^^^^^^^^^^^^^^^^^^^^^^^^^^^^^^^^^^^^^^
  File "C:\Program Files\Python313\Lib\asyncio\tasks.py", line 507, in wait_for
    return await fut
           ^^^^^^^^^
  File "C:\Users\colij\Documents\Repo_Tracker_Bot\env\Lib\site-packages\discord\gateway.py", line 375, in from_client
    socket = await client.http.ws_connect(str(url))
             ^^^^^^^^^^^^^^^^^^^^^^^^^^^^^^^^^^^^^^
  File "C:\Users\colij\Documents\Repo_Tracker_Bot\env\Lib\site-packages\discord\http.py", line 554, in ws_connect
    return await self.__session.ws_connect(url, **kwargs)
           ^^^^^^^^^^^^^^^^^^^^^^^^^^^^^^^^^^^^^^^^^^^^^^
  File "C:\Users\colij\Documents\Repo_Tracker_Bot\env\Lib\site-packages\aiohttp\client.py", line 1004, in _ws_connect
    resp = await self.request(
           ^^^^^^^^^^^^^^^^^^^
    ...<11 lines>...
    )
    ^
  File "C:\Users\colij\Documents\Repo_Tracker_Bot\env\Lib\site-packages\aiohttp\client.py", line 703, in _request
    conn = await self._connector.connect(
           ^^^^^^^^^^^^^^^^^^^^^^^^^^^^^^
        req, traces=traces, timeout=real_timeout
        ^^^^^^^^^^^^^^^^^^^^^^^^^^^^^^^^^^^^^^^^
    )
    ^
  File "C:\Users\colij\Documents\Repo_Tracker_Bot\env\Lib\site-packages\aiohttp\connector.py", line 548, in connect
    proto = await self._create_connection(req, traces, timeout)
            ^^^^^^^^^^^^^^^^^^^^^^^^^^^^^^^^^^^^^^^^^^^^^^^^^^^
  File "C:\Users\colij\Documents\Repo_Tracker_Bot\env\Lib\site-packages\aiohttp\connector.py", line 1056, in _create_connection
    _, proto = await self._create_direct_connection(req, traces, timeout)
               ^^^^^^^^^^^^^^^^^^^^^^^^^^^^^^^^^^^^^^^^^^^^^^^^^^^^^^^^^^
  File "C:\Users\colij\Documents\Repo_Tracker_Bot\env\Lib\site-packages\aiohttp\connector.py", line 1357, in _create_direct_connection
    raise ClientConnectorDNSError(req.connection_key, exc) from exc
aiohttp.client_exceptions.ClientConnectorDNSError: Cannot connect to host gateway-us-east1-c.discord.gg:443 ssl:default [getaddrinfo failed]
2025-04-23 23:48:10,605:INFO:discord.gateway: Shard ID None has successfully RESUMED session 1b08198be2cb3225db8dec2e93b9b351.
2025-04-23 23:49:34,834:INFO:discord.gateway: Shard ID None has successfully RESUMED session 1b08198be2cb3225db8dec2e93b9b351.
2025-04-23 23:51:31,878:INFO:discord: Checking for new commits...
2025-04-23 23:51:33,145:INFO:discord: No new commits found.
2025-04-23 23:56:31,883:INFO:discord: Checking for new commits...
2025-04-23 23:56:32,299:INFO:discord: No new commits found.
2025-04-24 00:01:31,882:INFO:discord: Checking for new commits...
2025-04-24 00:01:33,172:INFO:discord: No new commits found.
